Workbook

Sheet Summary IS
A1: Metric | C1: 2023A | D1: 2024A | E1: 2025A | F1: 2026 YTD | G1: 2026F | H1: 2027F | I1: 2028F | J1: 2029F | K1: 2030F | L1: 2031F
A2: Period Type | C2: Actual | D2: Actual | E2: Actual | F2: YTD Actual | G2: Forecast | H2: Forecast | I2: Forecast | J2: Forecast | K2: Forecast | L2: Forecast
A3: Months in period | C3: 12 | D3: 12 | E3: 12 | F3: 8 | G3: 4 | H3: 12 | I3: 12 | J3: 12 | K3: 12 | L3: 12 | N3: Hardcoded input | O3: Blue font
N4: Same-sheet formula | O4: Black font
A5: Summary Income Statement | N5: Cross-sheet link | O5: Green font
N6: Attention / review | O6: Yellow fill
A7: Revenue Scenario Comparison
A8: Bottom-Up / YAU Platform Revenue | C8: =Revenue_B!C11 -> 304 | D8: =Revenue_B!D11 -> 84.79 | E8: =Revenue_B!E11 -> 898.42 | F8: =Revenue_B!F11 -> 512.15 | G8: =Revenue_B!G11 -> 1037.625 | H8: =Revenue_B!H11 -> 54703.406 | I8: =Revenue_B!I11 -> 229476.32 | J8: =Revenue_B!J11 -> 673264.94 | ... L8: =Revenue_B!L11 -> 3566760.9
A9: Top-Down Platform Revenue | H9: =Revenue_T!D12 -> 6649.5813 | I9: =Revenue_T!E12 -> 44216.931 | J9: =Revenue_T!F12 -> 294024.08 | K9: =Revenue_T!G12 -> 1955137 | L9: =Revenue_T!H12 -> 13000843
A10: Top-Down Less Bottom-Up | H10: =IF(OR(H8="",H9=""),"",H9-H8) -> -48053.825 | I10: =IF(OR(I8="",I9=""),"",I9-I8) -> -185259.39 | J10: =IF(OR(J8="",J9=""),"",J9-J8) -> -379240.86 | K10: =IF(OR(K8="",K9=""),"",K9-K8) -> 304856.55 | L10: =IF(OR(L8="",L9=""),"",L9-L8) -> 9434081.7
A11: Top-Down / Bottom-Up | H11: =IF(OR(H8="",H8=0,H9=""),"",H9/H8) -> 0.12155699 | I11: =IF(OR(I8="",I8=0,I9=""),"",I9/I8) -> 0.19268625 | J11: =IF(OR(J8="",J8=0,J9=""),"",J9/J8) -> 0.43671379 | K11: =IF(OR(K8="",K8=0,K9=""),"",K9/K8) -> 1.1847301 | L11: =IF(OR(L8="",L8=0,L9=""),"",L9/L8) -> 3.6449998
A13: Bottom-Up / YAU Case
A14: Platform Revenue | C14: =Revenue_B!C11 -> 304 | D14: =Revenue_B!D11 -> 84.79 | E14: =Revenue_B!E11 -> 898.42 | F14: =Revenue_B!F11 -> 512.15 | G14: =Revenue_B!G11 -> 1037.625 | H14: =Revenue_B!H11 -> 54703.406 | I14: =Revenue_B!I11 -> 229476.32 | J14: =Revenue_B!J11 -> 673264.94 | ... L14: =Revenue_B!L11 -> 3566760.9
A15: Transaction / Platform Costs | C15: =IF(C14="","",Expenses_Y!C65) -> 0 | D15: =IF(D14="","",Expenses_Y!D65) -> 0 | E15: =IF(E14="","",Expenses_Y!E65) -> 0 | F15: =IF(F14="","",Expenses_Y!F65) -> 0 | G15: =IF(G14="","",Expenses_Y!G65) -> 0 | H15: =IF(H14="","",Expenses_Y!H65) -> 0 | I15: =IF(I14="","",Expenses_Y!I65) -> 0 | J15: =IF(J14="","",Expenses_Y!J65) -> 0 | ... L15: =IF(L14="","",Expenses_Y!L65) -> 0
A16: Gross Profit | C16: =IF(C14="","",C14-C15) -> 304 | D16: =IF(D14="","",D14-D15) -> 84.79 | E16: =IF(E14="","",E14-E15) -> 898.42 | F16: =IF(F14="","",F14-F15) -> 512.15 | G16: =IF(G14="","",G14-G15) -> 1037.625 | H16: =IF(H14="","",H14-H15) -> 54703.406 | I16: =IF(I14="","",I14-I15) -> 229476.32 | J16: =IF(J14="","",J14-J15) -> 673264.94 | ... L16: =IF(L14="","",L14-L15) -> 3566760.9
A17: Gross Margin % | C17: =IF(OR(C14="",C14=0,C16=""),"",C16/C14) -> 1 | D17: =IF(OR(D14="",D14=0,D16=""),"",D16/D14) -> 1 | E17: =IF(OR(E14="",E14=0,E16=""),"",E16/E14) -> 1 | F17: =IF(OR(F14="",F14=0,F16=""),"",F16/F14) -> 1 | G17: =IF(OR(G14="",G14=0,G16=""),"",G16/G14) -> 1 | H17: =IF(OR(H14="",H14=0,H16=""),"",H16/H14) -> 1 | I17: =IF(OR(I14="",I14=0,I16=""),"",I16/I14) -> 1 | J17: =IF(OR(J14="",J14=0,J16=""),"",J16/J14) -> 1 | ... L17: =IF(OR(L14="",L14=0,L16=""),"",L16/L14) -> 1
A19: Personnel Expense | C19: =IF(C14="","",Expenses_Y!C37) -> 0 | D19: =IF(D14="","",Expenses_Y!D37) -> 0 | E19: =IF(E14="","",Expenses_Y!E37) -> 0 | F19: =IF(F14="","",Expenses_Y!F37) -> 0 | G19: =IF(G14="","",Expenses_Y!G37) -> 33333.333 | H19: =IF(H14="","",Expenses_Y!H37) -> 210000 | I19: =IF(I14="","",Expenses_Y!I37) -> 371000 | J19: =IF(J14="","",Expenses_Y!J37) -> 833100 | ... L19: =IF(L14="","",Expenses_Y!L37) -> 1061051
A20: Technology & Infrastructure | C20: =IF(C14="","",Expenses_Y!C43) -> 2128 | D20: =IF(D14="","",Expenses_Y!D43) -> 2128 | E20: =IF(E14="","",Expenses_Y!E43) -> 2128 | F20: =IF(F14="","",Expenses_Y!F43) -> 528 | G20: =IF(G14="","",Expenses_Y!G43) -> 0 | H20: =IF(H14="","",Expenses_Y!H43) -> 0 | I20: =IF(I14="","",Expenses_Y!I43) -> 0 | J20: =IF(J14="","",Expenses_Y!J43) -> 0 | ... L20: =IF(L14="","",Expenses_Y!L43) -> 0
A21: Sales & Marketing | C21: =IF(C14="","",Expenses_Y!C51) -> 0 | D21: =IF(D14="","",Expenses_Y!D51) -> 0 | E21: =IF(E14="","",Expenses_Y!E51) -> 0 | F21: =IF(F14="","",Expenses_Y!F51) -> 0 | G21: =IF(G14="","",Expenses_Y!G51) -> 5000 | H21: =IF(H14="","",Expenses_Y!H51) -> 10000 | I21: =IF(I14="","",Expenses_Y!I51) -> 15000 | J21: =IF(J14="","",Expenses_Y!J51) -> 20000 | ... L21: =IF(L14="","",Expenses_Y!L51) -> 0
A22: General & Administrative | C22: =IF(C14="","",Expenses_Y!C59) -> 500 | D22: =IF(D14="","",Expenses_Y!D59) -> 500 | E22: =IF(E14="","",Expenses_Y!E59) -> 500 | F22: =IF(F14="","",Expenses_Y!F59) -> 0 | G22: =IF(G14="","",Expenses_Y!G59) -> 0 | H22: =IF(H14="","",Expenses_Y!H59) -> 0 | I22: =IF(I14="","",Expenses_Y!I59) -> 0 | J22: =IF(J14="","",Expenses_Y!J59) -> 0 | ... L22: =IF(L14="","",Expenses_Y!L59) -> 0
A23: Total Operating Expenses | C23: =IF(C14="","",SUM(C19:C22)) -> 2628 | D23: =IF(D14="","",SUM(D19:D22)) -> 2628 | E23: =IF(E14="","",SUM(E19:E22)) -> 2628 | F23: =IF(F14="","",SUM(F19:F22)) -> 528 | G23: =IF(G14="","",SUM(G19:G22)) -> 38333.333 | H23: =IF(H14="","",SUM(H19:H22)) -> 220000 | I23: =IF(I14="","",SUM(I19:I22)) -> 386000 | J23: =IF(J14="","",SUM(J19:J22)) -> 853100 | ... L23: =IF(L14="","",SUM(L19:L22)) -> 1061051
A25: Operating Income | C25: =IF(C14="","",C16-C23) -> -2324 | D25: =IF(D14="","",D16-D23) -> -2543.21 | E25: =IF(E14="","",E16-E23) -> -1729.58 | F25: =IF(F14="","",F16-F23) -> -15.85 | G25: =IF(G14="","",G16-G23) -> -37295.708 | H25: =IF(H14="","",H16-H23) -> -165296.59 | I25: =IF(I14="","",I16-I23) -> -156523.68 | J25: =IF(J14="","",J16-J23) -> -179835.06 | ... L25: =IF(L14="","",L16-L23) -> 2505709.9
A26: Operating Margin % | C26: =IF(OR(C14="",C14=0,C25=""),"",C25/C14) -> -7.6447368 | D26: =IF(OR(D14="",D14=0,D25=""),"",D25/D14) -> -29.994221 | E26: =IF(OR(E14="",E14=0,E25=""),"",E25/E14) -> -1.9251352 | F26: =IF(OR(F14="",F14=0,F25=""),"",F25/F14) -> -0.030947964 | G26: =IF(OR(G14="",G14=0,G25=""),"",G25/G14) -> -35.94334 | H26: =IF(OR(H14="",H14=0,H25=""),"",H25/H14) -> -3.0216874 | I26: =IF(OR(I14="",I14=0,I25=""),"",I25/I14) -> -0.68209074 | J26: =IF(OR(J14="",J14=0,J25=""),"",J25/J14) -> -0.26710891 | ... L26: =IF(OR(L14="",L14=0,L25=""),"",L25/L14) -> 0.70251692
A28: Pre-Tax Income | C28: =IF(C25="","",C25) -> -2324 | D28: =IF(D25="","",D25) -> -2543.21 | E28: =IF(E25="","",E25) -> -1729.58 | F28: =IF(F25="","",F25) -> -15.85 | G28: =IF(G25="","",G25) -> -37295.708 | H28: =IF(H25="","",H25) -> -165296.59 | I28: =IF(I25="","",I25) -> -156523.68 | J28: =IF(J25="","",J25) -> -179835.06 | ... L28: =IF(L25="","",L25) -> 2505709.9
A29: Taxes | C29: =IF(C28="","",MAX(0,C28*$G$55)) -> 0 | D29: =IF(D28="","",MAX(0,D28*$G$55)) -> 0 | E29: =IF(E28="","",MAX(0,E28*$G$55)) -> 0 | F29: =IF(F28="","",MAX(0,F28*$G$55)) -> 0 | G29: =IF(G28="","",MAX(0,G28*$G$55)) -> 0 | H29: =IF(H28="","",MAX(0,H28*$G$55)) -> 0 | I29: =IF(I28="","",MAX(0,I28*$G$55)) -> 0 | J29: =IF(J28="","",MAX(0,J28*$G$55)) -> 0 | ... L29: =IF(L28="","",MAX(0,L28*$G$55)) -> 526199.07
A30: Net Income | C30: =IF(C28="","",C28-C29) -> -2324 | D30: =IF(D28="","",D28-D29) -> -2543.21 | E30: =IF(E28="","",E28-E29) -> -1729.58 | F30: =IF(F28="","",F28-F29) -> -15.85 | G30: =IF(G28="","",G28-G29) -> -37295.708 | H30: =IF(H28="","",H28-H29) -> -165296.59 | I30: =IF(I28="","",I28-I29) -> -156523.68 | J30: =IF(J28="","",J28-J29) -> -179835.06 | ... L30: =IF(L28="","",L28-L29) -> 1979510.8
A31: Net Margin % | C31: =IF(OR(C14="",C14=0,C30=""),"",C30/C14) -> -7.6447368 | D31: =IF(OR(D14="",D14=0,D30=""),"",D30/D14) -> -29.994221 | E31: =IF(OR(E14="",E14=0,E30=""),"",E30/E14) -> -1.9251352 | F31: =IF(OR(F14="",F14=0,F30=""),"",F30/F14) -> -0.030947964 | G31: =IF(OR(G14="",G14=0,G30=""),"",G30/G14) -> -35.94334 | H31: =IF(OR(H14="",H14=0,H30=""),"",H30/H14) -> -3.0216874 | I31: =IF(OR(I14="",I14=0,I30=""),"",I30/I14) -> -0.68209074 | J31: =IF(OR(J14="",J14=0,J30=""),"",J30/J14) -> -0.26710891 | ... L31: =IF(OR(L14="",L14=0,L30=""),"",L30/L14) -> 0.55498837
A33: Top-Down Case
A34: Platform Revenue | H34: =Revenue_T!D12 -> 6649.5813 | I34: =Revenue_T!E12 -> 44216.931 | J34: =Revenue_T!F12 -> 294024.08 | K34: =Revenue_T!G12 -> 1955137 | L34: =Revenue_T!H12 -> 13000843
A35: Transaction / Platform Costs | H35: =IF(H34="","",Expenses_Y!H65) -> 0 | I35: =IF(I34="","",Expenses_Y!I65) -> 0 | J35: =IF(J34="","",Expenses_Y!J65) -> 0 | K35: =IF(K34="","",Expenses_Y!K65) -> 0 | L35: =IF(L34="","",Expenses_Y!L65) -> 0
A36: Gross Profit | H36: =IF(H34="","",H34-H35) -> 6649.5813 | I36: =IF(I34="","",I34-I35) -> 44216.931 | J36: =IF(J34="","",J34-J35) -> 294024.08 | K36: =IF(K34="","",K34-K35) -> 1955137 | L36: =IF(L34="","",L34-L35) -> 13000843
A37: Gross Margin % | H37: =IF(OR(H34="",H34=0,H36=""),"",H36/H34) -> 1 | I37: =IF(OR(I34="",I34=0,I36=""),"",I36/I34) -> 1 | J37: =IF(OR(J34="",J34=0,J36=""),"",J36/J34) -> 1 | K37: =IF(OR(K34="",K34=0,K36=""),"",K36/K34) -> 1 | L37: =IF(OR(L34="",L34=0,L36=""),"",L36/L34) -> 1
A39: Personnel Expense | H39: =IF(H34="","",Expenses_Y!H37) -> 210000 | I39: =IF(I34="","",Expenses_Y!I37) -> 371000 | J39: =IF(J34="","",Expenses_Y!J37) -> 833100 | K39: =IF(K34="","",Expenses_Y!K37) -> 1046410 | L39: =IF(L34="","",Expenses_Y!L37) -> 1061051
A40: Technology & Infrastructure | H40: =IF(H34="","",Expenses_Y!H43) -> 0 | I40: =IF(I34="","",Expenses_Y!I43) -> 0 | J40: =IF(J34="","",Expenses_Y!J43) -> 0 | K40: =IF(K34="","",Expenses_Y!K43) -> 0 | L40: =IF(L34="","",Expenses_Y!L43) -> 0
A41: Sales & Marketing | H41: =IF(H34="","",Expenses_Y!H51) -> 10000 | I41: =IF(I34="","",Expenses_Y!I51) -> 15000 | J41: =IF(J34="","",Expenses_Y!J51) -> 20000 | K41: =IF(K34="","",Expenses_Y!K51) -> 25000 | L41: =IF(L34="","",Expenses_Y!L51) -> 0
A42: General & Administrative | H42: =IF(H34="","",Expenses_Y!H59) -> 0 | I42: =IF(I34="","",Expenses_Y!I59) -> 0 | J42: =IF(J34="","",Expenses_Y!J59) -> 0 | K42: =IF(K34="","",Expenses_Y!K59) -> 0 | L42: =IF(L34="","",Expenses_Y!L59) -> 0
A43: Total Operating Expenses | H43: =IF(H34="","",SUM(H39:H42)) -> 220000 | I43: =IF(I34="","",SUM(I39:I42)) -> 386000 | J43: =IF(J34="","",SUM(J39:J42)) -> 853100 | K43: =IF(K34="","",SUM(K39:K42)) -> 1071410 | L43: =IF(L34="","",SUM(L39:L42)) -> 1061051
A45: Operating Income | H45: =IF(H34="","",H36-H43) -> -213350.42 | I45: =IF(I34="","",I36-I43) -> -341783.07 | J45: =IF(J34="","",J36-J43) -> -559075.92 | K45: =IF(K34="","",K36-K43) -> 883727.02 | L45: =IF(L34="","",L36-L43) -> 11939792
A46: Operating Margin % | H46: =IF(OR(H34="",H34=0,H45=""),"",H45/H34) -> -32.08479 | I46: =IF(OR(I34="",I34=0,I45=""),"",I45/I34) -> -7.7296876 | J46: =IF(OR(J34="",J34=0,J45=""),"",J45/J34) -> -1.901463 | K46: =IF(OR(K34="",K34=0,K45=""),"",K45/K34) -> 0.4520026 | L46: =IF(OR(L34="",L34=0,L45=""),"",L45/L34) -> 0.91838598
A48: Pre-Tax Income | H48: =IF(H45="","",H45) -> -213350.42 | I48: =IF(I45="","",I45) -> -341783.07 | J48: =IF(J45="","",J45) -> -559075.92 | K48: =IF(K45="","",K45) -> 883727.02 | L48: =IF(L45="","",L45) -> 11939792
...

Sheet Revenue_T
C1: 2026A | D1: =IF(1<=$C$24,"2027F","") -> 2027F | E1: =IF(2<=$C$24,"2028F","") -> 2028F | F1: =IF(3<=$C$24,"2029F","") -> 2029F | G1: =IF(4<=$C$24,"2030F","") -> 2030F | H1: =IF(5<=$C$24,"2031F","") -> 2031F | I1: =IF(6<=$C$24,"2032F","") -> 2032F | J1: =IF(7<=$C$24,"2033F","") -> 2033F | K1: =IF(8<=$C$24,"2034F","") | L1: =IF(9<=$C$24,"2035F","") | M1: =IF(10<=$C$24,"2036F","") | N1: =IF(11<=$C$24,"2037F","") | O1: =IF(12<=$C$24,"2038F","") | P1: =IF(13<=$C$24,"2039F","") | Q1: =IF(14<=$C$24,"2040F","") | R1: =IF(15<=$C$24,"2041F","") | XFA1: 0.001 | XFB1: 0.05 | XFC1: 0.05 | XFD1: 100
C2: Actual | D2: Forecast | E2: Forecast | F2: Forecast | G2: Forecast | H2: Forecast | I2: Forecast | J2: Forecast | K2: =IF(K$1<>"","Forecast","") | L2: =IF(L$1<>"","Forecast","") | M2: =IF(M$1<>"","Forecast","") | N2: =IF(N$1<>"","Forecast","") | O2: =IF(O$1<>"","Forecast","") | P2: =IF(P$1<>"","Forecast","") | Q2: =IF(Q$1<>"","Forecast","") | R2: =IF(R$1<>"","Forecast","") | XFA2: 0.002 | XFB2: 0.1 | XFC2: 0.1 | XFD2: 75
XFA3: 0.003 | XFB3: 0.15 | XFC3: 0.15 | XFD3: 114
A4: Top-Down Revenue Model | XFA4: 0.004 | XFB4: 0.2 | XFC4: 0.2 | XFD4: 7
XFA5: 0.005 | XFB5: 0.223 | XFC5: 0.25
A6: Annual Top-Down Revenue Forecast | XFA6: 0.006 | XFB6: 0.25 | XFC6: 0.3
A7: Global Market ($bn) | C7: =IF(0<=$C$24,$C$16*(1+$C$19)^0,"") -> 360 | D7: =IF(1<=$C$24,$C$16*(1+$C$19)^1,"") -> 401.04 | E7: =IF(2<=$C$24,$C$16*(1+$C$19)^2,"") -> 446.75856 | F7: =IF(3<=$C$24,$C$16*(1+$C$19)^3,"") -> 497.68904 | G7: =IF(4<=$C$24,$C$16*(1+$C$19)^4,"") -> 554.42559 | H7: =IF(5<=$C$24,$C$16*(1+$C$19)^5,"") -> 617.6301 | I7: =IF(6<=$C$24,$C$16*(1+$C$19)^6,"") -> 688.03993 | J7: =IF(7<=$C$24,$C$16*(1+$C$19)^7,"") -> 766.47649 | K7: =IF(8<=$C$24,$C$16*(1+$C$19)^8,"") | L7: =IF(9<=$C$24,$C$16*(1+$C$19)^9,"") | M7: =IF(10<=$C$24,$C$16*(1+$C$19)^10,"") | N7: =IF(11<=$C$24,$C$16*(1+$C$19)^11,"") | O7: =IF(12<=$C$24,$C$16*(1+$C$19)^12,"") | P7: =IF(13<=$C$24,$C$16*(1+$C$19)^13,"") | Q7: =IF(14<=$C$24,$C$16*(1+$C$19)^14,"") | R7: =IF(15<=$C$24,$C$16*(1+$C$19)^15,"") | XFA7: 0.007 | XFB7: 0.3 | XFC7: 0.35
A8: Market CAGR | C8: - | D8: =IF(D$1<>"",$C$19,"") -> 0.114 | E8: =IF(E$1<>"",$C$19,"") -> 0.114 | F8: =IF(F$1<>"",$C$19,"") -> 0.114 | G8: =IF(G$1<>"",$C$19,"") -> 0.114 | H8: =IF(H$1<>"",$C$19,"") -> 0.114 | I8: =IF(I$1<>"",$C$19,"") -> 0.114 | J8: =IF(J$1<>"",$C$19,"") -> 0.114 | K8: =IF(K$1<>"",$C$19,"") | ... R8: =IF(R$1<>"",$C$19,"") | XFA8: 0.008 | XFC8: 0.4
A9: Kahana-Relevant Segment % | C9: =IF(C$1<>"",$C$17,"") -> 0.075 | D9: =IF(D$1<>"",$C$17,"") -> 0.075 | E9: =IF(E$1<>"",$C$17,"") -> 0.075 | F9: =IF(F$1<>"",$C$17,"") -> 0.075 | G9: =IF(G$1<>"",$C$17,"") -> 0.075 | H9: =IF(H$1<>"",$C$17,"") -> 0.075 | I9: =IF(I$1<>"",$C$17,"") -> 0.075 | J9: =IF(J$1<>"",$C$17,"") -> 0.075 | ... R9: =IF(R$1<>"",$C$17,"") | XFA9: 0.009 | XFC9: 0.45
A10: Kahana-Relevant Global Market ($mm) | C10: =IF(C$1<>"",C7*1000*C9,"") -> 27000 | D10: =IF(D$1<>"",D7*1000*D9,"") -> 30078 | E10: =IF(E$1<>"",E7*1000*E9,"") -> 33506.892 | F10: =IF(F$1<>"",F7*1000*F9,"") -> 37326.678 | G10: =IF(G$1<>"",G7*1000*G9,"") -> 41581.919 | H10: =IF(H$1<>"",H7*1000*H9,"") -> 46322.258 | I10: =IF(I$1<>"",I7*1000*I9,"") -> 51602.995 | J10: =IF(J$1<>"",J7*1000*J9,"") -> 57485.737 | ... R10: =IF(R$1<>"",R7*1000*R9,"") | XFA10: 0.01 | XFC10: 0.5
A11: Kahana Market Share | C11: =$C$21 -> 3.7037037e-08 | D11: =IF(D$1="","",IF(2027=$C$25,$C$22,$C$21*(1+$C$23)^1)) -> 2.2107791e-07 | E11: =IF(E$1="","",IF(2028=$C$25,$C$22,$C$21*(1+$C$23)^2)) -> 1.3196369e-06 | F11: =IF(F$1="","",IF(2029=$C$25,$C$22,$C$21*(1+$C$23)^3)) -> 7.8770493e-06 | G11: =IF(G$1="","",IF(2030=$C$25,$C$22,$C$21*(1+$C$23)^4)) -> 4.7018923e-05 | H11: =IF(H$1="","",IF(2031=$C$25,$C$22,$C$21*(1+$C$23)^5)) -> 0.00028066081 | I11: =IF(I$1="","",IF(2032=$C$25,$C$22,$C$21*(1+$C$23)^6)) -> 0.0016752935 | J11: =IF(J$1="","",IF(2033=$C$25,$C$22,$C$21*(1+$C$23)^7)) -> 0.01 | K11: =IF(K$1="","",IF(2034=$C$25,$C$22,$C$21*(1+$C$23)^8)) | L11: =IF(L$1="","",IF(2035=$C$25,$C$22,$C$21*(1+$C$23)^9)) | M11: =IF(M$1="","",IF(2036=$C$25,$C$22,$C$21*(1+$C$23)^10)) | N11: =IF(N$1="","",IF(2037=$C$25,$C$22,$C$21*(1+$C$23)^11)) | O11: =IF(O$1="","",IF(2038=$C$25,$C$22,$C$21*(1+$C$23)^12)) | P11: =IF(P$1="","",IF(2039=$C$25,$C$22,$C$21*(1+$C$23)^13)) | Q11: =IF(Q$1="","",IF(2040=$C$25,$C$22,$C$21*(1+$C$23)^14)) | R11: =IF(R$1="","",IF(2041=$C$25,$C$22,$C$21*(1+$C$23)^15)) | XFA11: 0.011 | XFC11: 0.55
A12: Kahana Platform Revenue ($) | C12: =IF(C$1<>"",C10*1000000*C11,"") -> 1000 | D12: =IF(D$1<>"",D10*1000000*D11,"") -> 6649.5813 | E12: =IF(E$1<>"",E10*1000000*E11,"") -> 44216.931 | F12: =IF(F$1<>"",F10*1000000*F11,"") -> 294024.08 | G12: =IF(G$1<>"",G10*1000000*G11,"") -> 1955137 | H12: =IF(H$1<>"",H10*1000000*H11,"") -> 13000843 | I12: =IF(I$1<>"",I10*1000000*I11,"") -> 86450160 | J12: =IF(J$1<>"",J10*1000000*J11,"") -> 5.7485737e+08 | ... R12: =IF(R$1<>"",R10*1000000*R11,"") | XFA12: 0.012 | XFC12: 0.6
A13: YoY Platform Revenue Growth % | C13: - | D13: =IF(OR(D$1="",C12="",C12=0,D12=""),"",D12/C12-1) -> 5.6495813 | E13: =IF(OR(E$1="",D12="",D12=0,E12=""),"",E12/D12-1) -> 5.6495813 | F13: =IF(OR(F$1="",E12="",E12=0,F12=""),"",F12/E12-1) -> 5.6495813 | G13: =IF(OR(G$1="",F12="",F12=0,G12=""),"",G12/F12-1) -> 5.6495813 | H13: =IF(OR(H$1="",G12="",G12=0,H12=""),"",H12/G12-1) -> 5.6495813 | I13: =IF(OR(I$1="",H12="",H12=0,I12=""),"",I12/H12-1) -> 5.6495813 | J13: =IF(OR(J$1="",I12="",I12=0,J12=""),"",J12/I12-1) -> 5.6495813 | K13: =IF(K$1="","",IFERROR(K12/J12-1,0)) | L13: =IF(L$1="","",IFERROR(L12/K12-1,0)) | M13: =IF(M$1="","",IFERROR(M12/L12-1,0)) | N13: =IF(N$1="","",IFERROR(N12/M12-1,0)) | O13: =IF(O$1="","",IFERROR(O12/N12-1,0)) | P13: =IF(P$1="","",IFERROR(P12/O12-1,0)) | Q13: =IF(Q$1="","",IFERROR(Q12/P12-1,0)) | R13: =IF(R$1="","",IFERROR(R12/Q12-1,0)) | XFA13: 0.013 | XFC13: 0.65
XFA14: 0.014 | XFC14: 0.7
A15: Market Size Build & Key Inputs | XFA15: 0.018 | XFC15: 0.9
A16: 2026 Global Market ($bn) | C16: 360 | XFA16: 0.019 | XFC16: 0.95
A17: Kahana-Relevant Segment % | C17: =$XFD$2/1000 -> 0.075 | XFA17: 0.02 | XFC17: 1
A18: 2026 Kahana-Relevant Global Market ($mm) | C18: =C16*1000*C17 -> 27000 | XFA18: 0.021
A19: Market CAGR | C19: =$XFD$3/1000 -> 0.114 | XFA19: 0.022
A20: 2026 Kahana Actual Platform Revenue ($mm) | C20: 0.001 | XFA20: 0.023
A21: 2026 Implied Kahana Market Share | C21: =IF(OR(C18="",C18=0,C20=""),"",C20/C18) -> 3.7037037e-08 | XFA21: 0.024
A22: Target Kahana Market Share at Forecast End | C22: =$XFD$1/10000 -> 0.01 | XFA22: 0.025
A23: Required Market Share CAGR | C23: =IF(OR(C21<=0,C22<=0,C24<=0),0,(C22/C21)^(1/C24)-1) -> 4.9691035 | XFA23: 0.026
A24: Forecast Horizon (Years) | C24: =$XFD$4 -> 7 | XFA24: 0.027
A25: Forecast End Year | C25: =2026+C24 -> 2033 | XFA25: 0.028
XFA26: 0.029
A27: Methodology / Sources | XFA27: 0.031
A28: 2026 Kahana-Relevant Global Market = 2026 Global Market × Kahana-Relevant Segment %. | XFA28: 0.032
A29: Kahana competes globally in this top-down model. No U.S. market-share assumption is used. | XFA29: 0.033
A30: Kahana Market Share is measured within the Kahana-relevant global market. The selected target share is reached in the dynamically selected forecast end year. | XFA30: 0.034
A31: Market CAGR guideline: 22.3% from The Business Research Company Creatorplaces market research; used as a growth proxy and selectable assumption. | XFA31: 0.035
A32: https://www.thebusinessresearchcompany.com/report/creatorplaces-global-market-report | XFA32: 0.036
XFA33: 0.037
XFA34: 0.038
XFA35: 0.039
XFA36: 0.04
XFA37: 0.041
XFA38: 0.042
XFA39: 0.043
XFA40: 0.044
...

Sheet Revenue_B
A1: Metric | C1: 2023A | D1: 2024A | E1: 2025A | F1: 2026 YTD | G1: 2026F | H1: 2027F | I1: 2028F | J1: 2029F | K1: 2030F | L1: 2031F
A2: Period Type | C2: Actual | D2: Actual | E2: Actual | F2: Actual | G2: Forecast | H2: Forecast | I2: Forecast | J2: Forecast | K2: Forecast | L2: Forecast
A3: Months in period | C3: 12 | D3: 12 | E3: 12 | F3: 8 | G3: 4 | H3: 12 | I3: 12 | J3: 12 | K3: 12 | L3: 12
A5: Creator Marketing Campaign Pro Forma
A7: REVENUE SUMMARY
A8: Revenue Source | C8: 2023A | D8: 2024A | E8: 2025A | F8: 2026 YTD | G8: 2026F | H8: 2027F | I8: 2028F | J8: 2029F | K8: 2030F | L8: 2031F
A9: Subscription revenue | G9: =G135 -> 370 | H9: =H135 -> 32038.5 | I9: =I135 -> 139036.95 | J9: =J135 -> 411795.19 | K9: =K135 -> 1013255.3 | L9: =L135 -> 2194647.2
A10: Transaction-fee revenue | G10: =G136 -> 667.625 | H10: =H136 -> 22664.906 | I10: =I136 -> 90439.374 | J10: =J136 -> 261469.75 | K10: =K136 -> 637025.21 | L10: =L136 -> 1372113.7
A11: Total company revenue | C11: 304 | D11: 84.79 | E11: 898.42 | F11: 512.15 | G11: =SUM(G9:G10) -> 1037.625 | H11: =SUM(H9:H10) -> 54703.406 | I11: =SUM(I9:I10) -> 229476.32 | J11: =SUM(J9:J10) -> 673264.94 | K11: =SUM(K9:K10) -> 1650280.5 | L11: =SUM(L9:L10) -> 3566760.9
A13: PART A: CREATOR ACQUISITION ENGINE
A14: ENGINE 1: REACH -> Total contacted
A15: Number of interns / BDRs (from Expenses_Y) | C15: =Expenses_Y!C30 -> 0 | D15: =Expenses_Y!D30 -> 0 | E15: =Expenses_Y!E30 -> 0 | F15: =Expenses_Y!F30 -> 0 | G15: =Expenses_Y!G30 -> 10 | H15: =Expenses_Y!H30 -> 11 | I15: =Expenses_Y!I30 -> 12.1 | J15: =Expenses_Y!J30 -> 13.31 | ... L15: =Expenses_Y!L30 -> 16.1051
A16: Intern net hiring rate (from Expenses_Y, display only) | C16: =Expenses_Y!C31 -> 0 | D16: =Expenses_Y!D31 -> 0 | E16: =Expenses_Y!E31 -> 0 | F16: =Expenses_Y!F31 -> 0 | G16: =Expenses_Y!G31 -> 0 | H16: =Expenses_Y!H31 -> 0.1 | I16: =Expenses_Y!I31 -> 0.1 | J16: =Expenses_Y!J31 -> 0.1 | ... L16: =Expenses_Y!L31 -> 0.1
A17: Average salary per intern ($/year, from Expenses_Y) | C17: =Expenses_Y!C32 -> 0 | D17: =Expenses_Y!D32 -> 0 | E17: =Expenses_Y!E32 -> 0 | F17: =Expenses_Y!F32 -> 0 | G17: =Expenses_Y!G32 -> 10000 | H17: =Expenses_Y!H32 -> 10000 | I17: =Expenses_Y!I32 -> 10000 | J17: =Expenses_Y!J32 -> 10000 | ... L17: =Expenses_Y!L32 -> 10000
A18: Capacity per intern per month (base) | G18: 10 | H18: 10 | I18: 10 | J18: 10 | K18: 10 | L18: 10
A19: Intern incentive factor (extra contacts per $ of annual salary) | G19: 0.001 | H19: 0.001 | I19: 0.001 | J19: 0.001 | K19: 0.001 | L19: 0.001
A20: Capacity per intern per month (effective) | G20: =SUM(G18,G17*G19) -> 20 | H20: =SUM(H18,H17*H19) -> 20 | I20: =SUM(I18,I17*I19) -> 20 | J20: =SUM(J18,J17*J19) -> 20 | K20: =SUM(K18,K17*K19) -> 20 | L20: =SUM(L18,L17*L19) -> 20
A21: Contacts from headcount | G21: =G15*G20*G$3 -> 800 | H21: =H15*H20*H$3 -> 2640 | I21: =I15*I20*I$3 -> 2904 | J21: =J15*J20*J$3 -> 3194.4 | K21: =K15*K20*K$3 -> 3513.84 | L21: =L15*L20*L$3 -> 3865.224
A22: Outreach infra spend ($/year, from Expenses_Y) | C22: =Expenses_Y!C46 -> 0 | D22: =Expenses_Y!D46 -> 0 | E22: =Expenses_Y!E46 -> 0 | F22: =Expenses_Y!F46 -> 0 | G22: =Expenses_Y!G46 -> 5000 | H22: =Expenses_Y!H46 -> 0 | I22: =Expenses_Y!I46 -> 0 | J22: =Expenses_Y!J46 -> 0 | ... L22: =Expenses_Y!L46 -> 0
A23: Contacts from infra spend (base) | G23: 1000 | H23: 1000 | I23: 1000 | J23: 1000 | K23: 1000 | L23: 1000
A24: Spend conversion factor (extra contacts per $ spent) | G24: 0.01 | H24: 0.01 | I24: 0.01 | J24: 0.01 | K24: 0.01 | L24: 0.01
A25: Contacts from infra spend | G25: =SUM(G23,G22*G24) -> 1050 | H25: =SUM(H23,H22*H24) -> 1000 | I25: =SUM(I23,I22*I24) -> 1000 | J25: =SUM(J23,J22*J24) -> 1000 | K25: =SUM(K23,K22*K24) -> 1000 | L25: =SUM(L23,L22*L24) -> 1000
A26: Total contacted | G26: =SUM(G21,G25) -> 1850 | H26: =SUM(H21,H25) -> 3640 | I26: =SUM(I21,I25) -> 3904 | J26: =SUM(J21,J25) -> 4194.4 | K26: =SUM(K21,K25) -> 4513.84 | L26: =SUM(L21,L25) -> 4865.224
A28: ENGINE 2: CONVERSION -> Effective conversion rate
A29: Base conversion rate (input; carried forward) | G29: 0.1 | H29: =G29 -> 0.1 | I29: =H29 -> 0.1 | J29: =I29 -> 0.1 | K29: =J29 -> 0.1 | L29: =K29 -> 0.1
A30: CEO cash compensation (from Expenses_Y) | C30: =Expenses_Y!C19 -> 0 | D30: =Expenses_Y!D19 -> 0 | E30: =Expenses_Y!E19 -> 0 | F30: =Expenses_Y!F19 -> 0 | G30: =Expenses_Y!G19 -> 0 | H30: =Expenses_Y!H19 -> 100000 | I30: =Expenses_Y!I19 -> 100000 | J30: =Expenses_Y!J19 -> 100000 | ... L30: =Expenses_Y!L19 -> 100000
A31: CEO % time on personal touch outreach | G31: 0 | H31: 0 | I31: 0 | J31: 0 | K31: 0 | L31: 0
A32: Personal touch spend (annual) | G32: =G30*G31 -> 0 | H32: =H30*H31 -> 0 | I32: =I30*I31 -> 0 | J32: =J30*J31 -> 0 | K32: =K30*K31 -> 0 | L32: =L30*L31 -> 0
A33: Personal touch max lift (cap) | G33: 0.2 | H33: 0.2 | I33: 0.2 | J33: 0.2 | K33: 0.2 | L33: 0.2
A34: Personal touch half-saturation spend ($) | G34: 10000 | H34: 10000 | I34: 10000 | J34: 10000 | K34: 10000 | L34: 10000
A35: Personal touch lift (diminishing returns) | G35: =IF(OR(G32="",G34="",G32+G34=0),"",G33*G32/(G32+G34)) -> 0 | H35: =IF(OR(H32="",H34="",H32+H34=0),"",H33*H32/(H32+H34)) -> 0 | I35: =IF(OR(I32="",I34="",I32+I34=0),"",I33*I32/(I32+I34)) -> 0 | J35: =IF(OR(J32="",J34="",J32+J34=0),"",J33*J32/(J32+J34)) -> 0 | K35: =IF(OR(K32="",K34="",K32+K34=0),"",K33*K32/(K32+K34)) -> 0 | L35: =IF(OR(L32="",L34="",L32+L34=0),"",L33*L32/(L32+L34)) -> 0
A36: PM and Engineering cash compensation (from Expenses_Y) | C36: =Expenses_Y!C25+Expenses_Y!C22 -> 0 | D36: =Expenses_Y!D25+Expenses_Y!D22 -> 0 | E36: =Expenses_Y!E25+Expenses_Y!E22 -> 0 | F36: =Expenses_Y!F25+Expenses_Y!F22 -> 0 | G36: =Expenses_Y!G25+Expenses_Y!G22 -> 0 | H36: =Expenses_Y!H25+Expenses_Y!H22 -> 0 | I36: =Expenses_Y!I25+Expenses_Y!I22 -> 75000 | J36: =Expenses_Y!J25+Expenses_Y!J22 -> 225000 | ... L36: =Expenses_Y!L25+Expenses_Y!L22 -> 225000
A37: PM/eng % time on platform improvements | G37: 0 | H37: 0 | I37: 0 | J37: 0 | K37: 0 | L37: 0
A38: Platform improvement spend (annual) | G38: =G36*G37 -> 0 | H38: =H36*H37 -> 0 | I38: =I36*I37 -> 0 | J38: =J36*J37 -> 0 | K38: =K36*K37 -> 0 | L38: =L36*L37 -> 0
A39: Platform max lift (cap) | G39: 0.15 | H39: 0.15 | I39: 0.15 | J39: 0.15 | K39: 0.15 | L39: 0.15
A40: Platform half-saturation spend ($) | G40: 15000 | H40: 15000 | I40: 15000 | J40: 15000 | K40: 15000 | L40: 15000
A41: Platform lift (diminishing returns) | G41: =IF(OR(G38="",G40="",G38+G40=0),"",G39*G38/(G38+G40)) -> 0 | H41: =IF(OR(H38="",H40="",H38+H40=0),"",H39*H38/(H38+H40)) -> 0 | I41: =IF(OR(I38="",I40="",I38+I40=0),"",I39*I38/(I38+I40)) -> 0 | J41: =IF(OR(J38="",J40="",J38+J40=0),"",J39*J38/(J38+J40)) -> 0 | K41: =IF(OR(K38="",K40="",K38+K40=0),"",K39*K38/(K38+K40)) -> 0 | L41: =IF(OR(L38="",L40="",L38+L40=0),"",L39*L38/(L38+L40)) -> 0
A42: Effective conversion rate (capped 100%) | G42: =MIN(1,SUM(G29,G35,G41)) -> 0.1 | H42: =MIN(1,SUM(H29,H35,H41)) -> 0.1 | I42: =MIN(1,SUM(I29,I35,I41)) -> 0.1 | J42: =MIN(1,SUM(J29,J35,J41)) -> 0.1 | K42: =MIN(1,SUM(K29,K35,K41)) -> 0.1 | L42: =MIN(1,SUM(L29,L35,L41)) -> 0.1
A43: New creators (funnel = contacted x conversion) | G43: =G26*G42 -> 185 | H43: =H26*H42 -> 364 | I43: =I26*I42 -> 390.4 | J43: =J26*J42 -> 419.44 | K43: =K26*K42 -> 451.384 | L43: =L26*L42 -> 486.5224
A45: ENGINE 3: CPA -> New creators, direct (no funnel)
...

Sheet Expenses_Y
A1: Expense Forecast
A2: Personnel, technology, sales & marketing, G&A, and transaction costs. Decoupled from Seed Raise Plan - headcount and compensation are direct inputs.
A4: Metric | C4: 2023A | D4: 2024A | E4: 2025A | F4: 2026 YTD | G4: 2026F | H4: 2027F | I4: 2028F | J4: 2029F | K4: 2030F | L4: 2031F
A5: Period Type | C5: Actual | D5: Actual | E5: Actual | F5: Actual | G5: Forecast | H5: Forecast | I5: Forecast | J5: Forecast | K5: Forecast | L5: Forecast
A6: Months in Period | C6: 12 | D6: 12 | E6: 12 | F6: 8 | G6: 4 | H6: 12 | I6: 12 | J6: 12 | K6: 12 | L6: 12
A8: EXPENSE SUMMARY
A9: Personnel Expense | C9: =C37 -> 0 | D9: =D37 -> 0 | E9: =E37 -> 0 | F9: =F37 -> 0 | G9: =G37 -> 33333.333 | H9: =H37 -> 210000 | I9: =I37 -> 371000 | J9: =J37 -> 833100 | ... L9: =L37 -> 1061051
A10: Technology & Infrastructure | C10: =C43 -> 2128 | D10: =D43 -> 2128 | E10: =E43 -> 2128 | F10: =F43 -> 528 | G10: =G43 -> 0 | H10: =H43 -> 0 | I10: =I43 -> 0 | J10: =J43 -> 0 | ... L10: =L43 -> 0
A11: Sales & Marketing | C11: =C51 -> 0 | D11: =D51 -> 0 | E11: =E51 -> 0 | F11: =F51 -> 0 | G11: =G51 -> 5000 | H11: =H51 -> 10000 | I11: =I51 -> 15000 | J11: =J51 -> 20000 | ... L11: =L51 -> 0
A12: General & Administrative | C12: =C59 -> 500 | D12: =D59 -> 500 | E12: =E59 -> 500 | F12: =F59 -> 0 | G12: =G59 -> 0 | H12: =H59 -> 0 | I12: =I59 -> 0 | J12: =J59 -> 0 | ... L12: =L59 -> 0
A13: Transaction / Platform Costs | C13: =C65 -> 0 | D13: =D65 -> 0 | E13: =E65 -> 0 | F13: =F65 -> 0 | G13: =G65 -> 0 | H13: =H65 -> 0 | I13: =I65 -> 0 | J13: =J65 -> 0 | ... L13: =L65 -> 0
A14: Total Expenses | C14: =SUM(C9:C13) -> 2628 | D14: =SUM(D9:D13) -> 2628 | E14: =SUM(E9:E13) -> 2628 | F14: =SUM(F9:F13) -> 528 | G14: =SUM(G9:G13) -> 38333.333 | H14: =SUM(H9:H13) -> 220000 | I14: =SUM(I9:I13) -> 386000 | J14: =SUM(J9:J13) -> 853100 | ... L14: =SUM(L9:L13) -> 1061051
A15: YoY Expense Growth % | D15: =IF(OR(C14="",C14=0,D14=""),"",D14/C14-1) -> 0 | E15: =IF(OR(D14="",D14=0,E14=""),"",E14/D14-1) -> 0 | I15: =IF(OR(I14="",H14="",H14=0),"",I14/H14-1) -> 0.75454545 | J15: =IF(OR(J14="",I14="",I14=0),"",J14/I14-1) -> 1.2101036 | K15: =IF(OR(K14="",J14="",J14=0),"",K14/J14-1) -> 0.255902 | L15: =IF(OR(L14="",K14="",K14=0),"",L14/K14-1) -> -0.0096685676
A17: PERSONNEL
A18: CEO - Average FTE | C18: 0 | D18: 0 | E18: 0 | F18: 0 | G18: 0 | H18: 1 | I18: =H18 -> 1 | J18: =I18 -> 1 | K18: =J18 -> 1 | L18: =K18 -> 1
A19: CEO - Cash Compensation / FTE ($) | C19: 0 | D19: 0 | E19: 0 | F19: 0 | G19: 0 | H19: 100000 | I19: =H19 -> 100000 | J19: =I19 -> 100000 | K19: =J19 -> 100000 | L19: =K19 -> 100000
A20: CEO Compensation | C20: =IF(OR(C18="",C19=""),"",C18*C19*C$6/12) -> 0 | D20: =IF(OR(D18="",D19=""),"",D18*D19*D$6/12) -> 0 | E20: =IF(OR(E18="",E19=""),"",E18*E19*E$6/12) -> 0 | F20: =IF(OR(F18="",F19=""),"",F18*F19*F$6/12) -> 0 | G20: =IF(OR(G18="",G19=""),"",G18*G19*G$6/12) -> 0 | H20: =IF(OR(H18="",H19=""),"",H18*H19*H$6/12) -> 100000 | I20: =IF(OR(I18="",I19=""),"",I18*I19*I$6/12) -> 100000 | J20: =IF(OR(J18="",J19=""),"",J18*J19*J$6/12) -> 100000 | ... L20: =IF(OR(L18="",L19=""),"",L18*L19*L$6/12) -> 100000
A21: Engineering - Average FTE | C21: 0 | D21: 0 | E21: 0 | F21: 0 | G21: 0 | H21: 0 | I21: 2 | J21: =I21 -> 2 | K21: =J21 -> 2 | L21: =K21 -> 2
A22: Engineering - Cash Compensation / FTE ($) | C22: 0 | D22: 0 | E22: 0 | F22: 0 | G22: 0 | H22: 0 | I22: 75000 | J22: =I22 -> 75000 | K22: =J22 -> 75000 | L22: =K22 -> 75000
A23: Engineering Compensation | C23: =IF(OR(C21="",C22=""),"",C21*C22*C$6/12) -> 0 | D23: =IF(OR(D21="",D22=""),"",D21*D22*D$6/12) -> 0 | E23: =IF(OR(E21="",E22=""),"",E21*E22*E$6/12) -> 0 | F23: =IF(OR(F21="",F22=""),"",F21*F22*F$6/12) -> 0 | G23: =IF(OR(G21="",G22=""),"",G21*G22*G$6/12) -> 0 | H23: =IF(OR(H21="",H22=""),"",H21*H22*H$6/12) -> 0 | I23: =IF(OR(I21="",I22=""),"",I21*I22*I$6/12) -> 150000 | J23: =IF(OR(J21="",J22=""),"",J21*J22*J$6/12) -> 150000 | ... L23: =IF(OR(L21="",L22=""),"",L21*L22*L$6/12) -> 150000
A24: Product - Average FTE | C24: 0 | D24: 0 | E24: 0 | F24: 0 | G24: 0 | H24: 0 | I24: 0 | J24: 3 | K24: =J24 -> 3 | L24: =K24 -> 3
A25: Product - Cash Compensation / FTE ($) | C25: 0 | D25: 0 | E25: 0 | F25: 0 | G25: 0 | H25: 0 | I25: 0 | J25: 150000 | K25: =J25 -> 150000 | L25: =K25 -> 150000
A26: Product Compensation | C26: =IF(OR(C24="",C25=""),"",C24*C25*C$6/12) -> 0 | D26: =IF(OR(D24="",D25=""),"",D24*D25*D$6/12) -> 0 | E26: =IF(OR(E24="",E25=""),"",E24*E25*E$6/12) -> 0 | F26: =IF(OR(F24="",F25=""),"",F24*F25*F$6/12) -> 0 | G26: =IF(OR(G24="",G25=""),"",G24*G25*G$6/12) -> 0 | H26: =IF(OR(H24="",H25=""),"",H24*H25*H$6/12) -> 0 | I26: =IF(OR(I24="",I25=""),"",I24*I25*I$6/12) -> 0 | J26: =IF(OR(J24="",J25=""),"",J24*J25*J$6/12) -> 450000 | ... L26: =IF(OR(L24="",L25=""),"",L24*L25*L$6/12) -> 450000
A27: Chief of Staff / Operations - Average FTE | C27: 0 | D27: 0 | E27: 0 | F27: 0 | G27: 0 | H27: 0 | I27: 0 | J27: 0 | K27: 4 | L27: =K27 -> 4
A28: Chief of Staff / Operations - Cash Compensation / FTE ($) | C28: 0 | D28: 0 | E28: 0 | F28: 0 | G28: 0 | H28: 0 | I28: 0 | J28: 0 | K28: 50000 | L28: =K28 -> 50000
A29: Chief of Staff / Operations Compensation | C29: =IF(OR(C27="",C28=""),"",C27*C28*C$6/12) -> 0 | D29: =IF(OR(D27="",D28=""),"",D27*D28*D$6/12) -> 0 | E29: =IF(OR(E27="",E28=""),"",E27*E28*E$6/12) -> 0 | F29: =IF(OR(F27="",F28=""),"",F27*F28*F$6/12) -> 0 | G29: =IF(OR(G27="",G28=""),"",G27*G28*G$6/12) -> 0 | H29: =IF(OR(H27="",H28=""),"",H27*H28*H$6/12) -> 0 | I29: =IF(OR(I27="",I28=""),"",I27*I28*I$6/12) -> 0 | J29: =IF(OR(J27="",J28=""),"",J27*J28*J$6/12) -> 0 | ... L29: =IF(OR(L27="",L28=""),"",L27*L28*L$6/12) -> 200000
A30: Interns / BDR - Average FTE | C30: 0 | D30: 0 | E30: 0 | F30: 0 | G30: 10 | H30: =G30*(1+H31) -> 11 | I30: =H30*(1+I31) -> 12.1 | J30: =I30*(1+J31) -> 13.31 | K30: =J30*(1+K31) -> 14.641 | L30: =K30*(1+L31) -> 16.1051
A31: Interns / BDR - Hiring Rate (after attrition) | H31: 0.1 | I31: 0.1 | J31: 0.1 | K31: 0.1 | L31: 0.1
A32: Interns / BDR - Cash Compensation / FTE ($/year) | C32: 0 | D32: 0 | E32: 0 | F32: 0 | G32: 10000 | H32: 10000 | I32: 10000 | J32: 10000 | K32: 10000 | L32: 10000
A33: Interns / BDR Compensation | C33: =IF(OR(C30="",C32=""),"",C30*C32*C$6/12) -> 0 | D33: =IF(OR(D30="",D32=""),"",D30*D32*D$6/12) -> 0 | E33: =IF(OR(E30="",E32=""),"",E30*E32*E$6/12) -> 0 | F33: =IF(OR(F30="",F32=""),"",F30*F32*F$6/12) -> 0 | G33: =IF(OR(G30="",G32=""),"",G30*G32*G$6/12) -> 33333.333 | H33: =IF(OR(H30="",H32=""),"",H30*H32*H$6/12) -> 110000 | I33: =IF(OR(I30="",I32=""),"",I30*I32*I$6/12) -> 121000 | J33: =IF(OR(J30="",J32=""),"",J30*J32*J$6/12) -> 133100 | ... L33: =IF(OR(L30="",L32=""),"",L30*L32*L$6/12) -> 161051
A34: Total Cash Compensation | C34: =SUM(C20,C23,C26,C29,C33) -> 0 | D34: =SUM(D20,D23,D26,D29,D33) -> 0 | E34: =SUM(E20,E23,E26,E29,E33) -> 0 | F34: =SUM(F20,F23,F26,F29,F33) -> 0 | G34: =SUM(G20,G23,G26,G29,G33) -> 33333.333 | H34: =SUM(H20,H23,H26,H29,H33) -> 210000 | I34: =SUM(I20,I23,I26,I29,I33) -> 371000 | J34: =SUM(J20,J23,J26,J29,J33) -> 833100 | ... L34: =SUM(L20,L23,L26,L29,L33) -> 1061051
A35: Payroll Taxes & Benefits % | C35: 0 | D35: 0 | E35: 0 | F35: 0 | G35: 0 | H35: 0 | I35: 0 | J35: 0 | K35: 0 | L35: 0
A36: Payroll Taxes & Benefits | C36: =C34*C35 -> 0 | D36: =D34*D35 -> 0 | E36: =E34*E35 -> 0 | F36: =F34*F35 -> 0 | G36: =G34*G35 -> 0 | H36: =H34*H35 -> 0 | I36: =I34*I35 -> 0 | J36: =J34*J35 -> 0 | ... L36: =L34*L35 -> 0
A37: Total Personnel Expense | C37: =SUM(C34,C36) -> 0 | D37: =SUM(D34,D36) -> 0 | E37: =SUM(E34,E36) -> 0 | F37: =SUM(F34,F36) -> 0 | G37: =SUM(G34,G36) -> 33333.333 | H37: =SUM(H34,H36) -> 210000 | I37: =SUM(I34,I36) -> 371000 | J37: =SUM(J34,J36) -> 833100 | ... L37: =SUM(L34,L36) -> 1061051
A39: TECHNOLOGY & INFRASTRUCTURE
A40: Additional Cloud & Hosting | C40: 0 | D40: 0 | E40: 0 | F40: 0 | G40: 0 | H40: 0 | I40: 0 | J40: 0 | K40: 0 | L40: 0
A41: Software & Tools | C41: =SUM(C68:C74) -> 2128 | D41: =SUM(D68:D74) -> 2128 | E41: =SUM(E68:E74) -> 2128 | F41: =SUM(F68:F74) -> 528 | G41: 0 | H41: 0 | I41: 0 | J41: 0 | K41: 0 | L41: 0
A42: Other Technology | C42: 0 | D42: 0 | E42: 0 | F42: 0 | G42: 0 | H42: 0 | I42: 0 | J42: 0 | K42: 0 | L42: 0
A43: Total Technology & Infrastructure | C43: =SUM(C40:C42) -> 2128 | D43: =SUM(D40:D42) -> 2128 | E43: =SUM(E40:E42) -> 2128 | F43: =SUM(F40:F42) -> 528 | G43: =SUM(G40:G42) -> 0 | H43: =SUM(H40:H42) -> 0 | I43: =SUM(I40:I42) -> 0 | J43: =SUM(J40:J42) -> 0 | ... L43: =SUM(L40:L42) -> 0
A45: SALES & MARKETING
...

Sheet Checks
A1: Model Checks
A3: Check | B3: Year | C3: Actual | D3: Expected | E3: Difference | F3: Tolerance | G3: Status
A4: Base conversion rate is consistent across forecast years | B4: All forecast years | C4: =MAX(Revenue_B!G29:L29)-MIN(Revenue_B!G29:L29) -> 0 | D4: 0 | E4: =C4-D4 -> 0 | F4: 0.001 | G4: =IFERROR(IF(ABS(E4)<=F4,"OK","FAIL"),"FAIL") -> OK
A5: Forecast churn rates are within 0%-100% | B5: All forecast years | C5: =MAX(MAX(Revenue_B!G82:L83)-1,-MIN(Revenue_B!G82:L83),0) -> 0 | D5: 0 | E5: =C5-D5 -> 0 | F5: 0.001 | G5: =IFERROR(IF(ABS(E5)<=F5,"OK","FAIL"),"FAIL") -> OK
A6: 2026F creator types tie to ending total | B6: 2026F | C6: =SUM(Revenue_B!G87:G88) -> 239 | D6: =Revenue_B!G89 -> 239 | E6: =C6-D6 -> 0 | F6: 0.001 | G6: =IFERROR(IF(ABS(E6)<=F6,"OK","FAIL"),"FAIL") -> OK
A7: 2026F revenue summary ties to detail | B7: 2026F | C7: =Revenue_B!G11 -> 1037.625 | D7: =Revenue_B!G137 -> 1037.625 | E7: =C7-D7 -> 0 | F7: 0.001 | G7: =IFERROR(IF(ABS(E7)<=F7,"OK","FAIL"),"FAIL") -> OK
A8: 2026F marketing spend total ties | B8: 2026F | C8: =Revenue_B!G143 -> 38333.333 | D8: =SUM(Revenue_B!G140:G142) -> 38333.333 | E8: =C8-D8 -> 0 | F8: 0.001 | G8: =IFERROR(IF(ABS(E8)<=F8,"OK","FAIL"),"FAIL") -> OK
A9: 2027F creator types tie to ending total | B9: 2027F | C9: =SUM(Revenue_B!H87:H88) -> 1040.8625 | D9: =Revenue_B!H89 -> 1040.8625 | E9: =C9-D9 -> 0 | F9: 0.001 | G9: =IFERROR(IF(ABS(E9)<=F9,"OK","FAIL"),"FAIL") -> OK
A10: 2027F revenue summary ties to detail | B10: 2027F | C10: =Revenue_B!H11 -> 54703.406 | D10: =Revenue_B!H137 -> 54703.406 | E10: =C10-D10 -> 0 | F10: 0.001 | G10: =IFERROR(IF(ABS(E10)<=F10,"OK","FAIL"),"FAIL") -> OK
A11: 2027F marketing spend total ties | B11: 2027F | C11: =Revenue_B!H143 -> 120000 | D11: =SUM(Revenue_B!H140:H142) -> 120000 | E11: =C11-D11 -> 0 | F11: 0.001 | G11: =IFERROR(IF(ABS(E11)<=F11,"OK","FAIL"),"FAIL") -> OK
A12: 2028F creator types tie to ending total | B12: 2028F | C12: =SUM(Revenue_B!I87:I88) -> 3197.1562 | D12: =Revenue_B!I89 -> 3197.1562 | E12: =C12-D12 -> 0 | F12: 0.001 | G12: =IFERROR(IF(ABS(E12)<=F12,"OK","FAIL"),"FAIL") -> OK
A13: 2028F revenue summary ties to detail | B13: 2028F | C13: =Revenue_B!I11 -> 229476.32 | D13: =Revenue_B!I137 -> 229476.32 | E13: =C13-D13 -> 0 | F13: 0.001 | G13: =IFERROR(IF(ABS(E13)<=F13,"OK","FAIL"),"FAIL") -> OK
A14: 2028F marketing spend total ties | B14: 2028F | C14: =Revenue_B!I143 -> 136000 | D14: =SUM(Revenue_B!I140:I142) -> 136000 | E14: =C14-D14 -> 0 | F14: 0.001 | G14: =IFERROR(IF(ABS(E14)<=F14,"OK","FAIL"),"FAIL") -> OK
A15: 2029F creator types tie to ending total | B15: 2029F | C15: =SUM(Revenue_B!J87:J88) -> 8404.1188 | D15: =Revenue_B!J89 -> 8404.1188 | E15: =C15-D15 -> 0 | F15: 0.001 | G15: =IFERROR(IF(ABS(E15)<=F15,"OK","FAIL"),"FAIL") -> OK
A16: 2029F revenue summary ties to detail | B16: 2029F | C16: =Revenue_B!J11 -> 673264.94 | D16: =Revenue_B!J137 -> 673264.94 | E16: =C16-D16 -> 0 | F16: 0.001 | G16: =IFERROR(IF(ABS(E16)<=F16,"OK","FAIL"),"FAIL") -> OK
A17: 2029F marketing spend total ties | B17: 2029F | C17: =Revenue_B!J143 -> 133100 | D17: =SUM(Revenue_B!J140:J142) -> 133100 | E17: =C17-D17 -> 0 | F17: 0.001 | G17: =IFERROR(IF(ABS(E17)<=F17,"OK","FAIL"),"FAIL") -> OK
A18: 2030F creator types tie to ending total | B18: 2030F | C18: =SUM(Revenue_B!K87:K88) -> 19621.98 | D18: =Revenue_B!K89 -> 19621.98 | E18: =C18-D18 -> 0 | F18: 0.001 | G18: =IFERROR(IF(ABS(E18)<=F18,"OK","FAIL"),"FAIL") -> OK
A19: 2030F revenue summary ties to detail | B19: 2030F | C19: =Revenue_B!K11 -> 1650280.5 | D19: =Revenue_B!K137 -> 1650280.5 | E19: =C19-D19 -> 0 | F19: 0.001 | G19: =IFERROR(IF(ABS(E19)<=F19,"OK","FAIL"),"FAIL") -> OK
A20: 2030F marketing spend total ties | B20: 2030F | C20: =Revenue_B!K143 -> 146410 | D20: =SUM(Revenue_B!K140:K142) -> 146410 | E20: =C20-D20 -> 0 | F20: 0.001 | G20: =IFERROR(IF(ABS(E20)<=F20,"OK","FAIL"),"FAIL") -> OK
A21: 2031F creator types tie to ending total | B21: 2031F | C21: =SUM(Revenue_B!L87:L88) -> 41226.163 | D21: =Revenue_B!L89 -> 41226.163 | E21: =C21-D21 -> 0 | F21: 0.001 | G21: =IFERROR(IF(ABS(E21)<=F21,"OK","FAIL"),"FAIL") -> OK
A22: 2031F revenue summary ties to detail | B22: 2031F | C22: =Revenue_B!L11 -> 3566760.9 | D22: =Revenue_B!L137 -> 3566760.9 | E22: =C22-D22 -> 0 | F22: 0.001 | G22: =IFERROR(IF(ABS(E22)<=F22,"OK","FAIL"),"FAIL") -> OK
A23: 2031F marketing spend total ties | B23: 2031F | C23: =Revenue_B!L143 -> 161051 | D23: =SUM(Revenue_B!L140:L142) -> 161051 | E23: =C23-D23 -> 0 | F23: 0.001 | G23: =IFERROR(IF(ABS(E23)<=F23,"OK","FAIL"),"FAIL") -> OK
A24: Summary IS Bottom-Up ties to Revenue_B (2027F) | B24: 2027F | C24: ='Summary IS'!H14 -> 54703.406 | D24: =Revenue_B!H11 -> 54703.406 | E24: =C24-D24 -> 0 | F24: 0.001 | G24: =IFERROR(IF(ABS(E24)<=F24,"OK","FAIL"),"FAIL") -> OK
A25: Summary IS Bottom-Up Personnel ties to Expenses_Y (2027F) | B25: 2027F | C25: ='Summary IS'!H19 -> 210000 | D25: =Expenses_Y!H37 -> 210000 | E25: =C25-D25 -> 0 | F25: 0.001 | G25: =IFERROR(IF(ABS(E25)<=F25,"OK","FAIL"),"FAIL") -> OK
A26: Summary IS Bottom-Up Transaction Costs ties to Expenses_Y (2027F) | B26: 2027F | C26: ='Summary IS'!H15 -> 0 | D26: =Expenses_Y!H65 -> 0 | E26: =C26-D26 -> 0 | F26: 0.001 | G26: =IFERROR(IF(ABS(E26)<=F26,"OK","FAIL"),"FAIL") -> OK
A27: Expenses_Y transaction costs tie to Revenue_B GMV x rate (2027F) | B27: 2027F | C27: =Expenses_Y!H63 -> 0 | D27: =Expenses_Y!H62*Revenue_B!H134 -> 0 | E27: =C27-D27 -> 0 | F27: 0.001 | G27: =IFERROR(IF(ABS(E27)<=F27,"OK","FAIL"),"FAIL") -> OK
A28: Expenses_Y Total Expenses ties to category sum (2027F) | B28: 2027F | C28: =Expenses_Y!H14 -> 220000 | D28: =SUM(Expenses_Y!H9:H13) -> 220000 | E28: =C28-D28 -> 0 | F28: 0.001 | G28: =IFERROR(IF(ABS(E28)<=F28,"OK","FAIL"),"FAIL") -> OK
A29: Summary IS Net Income = Pre-Tax minus Taxes, Bottom-Up (2027F) | B29: 2027F | C29: ='Summary IS'!H30 -> -165296.59 | D29: ='Summary IS'!H28-'Summary IS'!H29 -> -165296.59 | E29: =C29-D29 -> 0 | F29: 0.001 | G29: =IFERROR(IF(ABS(E29)<=F29,"OK","FAIL"),"FAIL") -> OK
A31: MODEL STATUS | G31: =IFERROR(IF(COUNTIF(G4:G29,"OK")=ROWS(G4:G29),"PASS","FAIL"),"FAIL") -> PASS

Sheet Comparable Companies
A2: Comparable Platform Financial Benchmarks
A3: Platform/company revenue unless ARR or GMV is explicitly labeled. Private-company figures may be estimates; use the Data Quality column when benchmarking Kahana.
A4: Platform / Scale | B4: Latest Revenue / ARR | D4: Cost / Profitability | F4: Data Quality | G4: Source URL(s)
A5: Stan Store ~70K creators; ~25-person team (2025) | B5: $25M revenue (2024) ~$41M ARR (2026) | D5: Profitable since 2022 seed round; detailed P&L not public | F5: High / Medium | G5: https://www.forbes.com/sites/victoriafeng/2025/08/12/this-startup-helps-creators-sell-classes-coaching-and-more-to-their-fans/ https://www.businessinsider.com/vibe-coded-7-figure-tool-startup-4-steps-followed-2026-7
A6: Beacons.ai Private creator platform; estimate-only financial data | B6: ~$10.8M revenue 2024 estimate | D6: No reliable public cost / profitability data located | F6: Low | G6: https://getlatka.com/companies/beacons.ai
A7: Kajabi >250 employees; >$11B creator revenue powered | B7: Close to $200M annual revenue 2026 company / investor commentary | D7: Historically bootstrapped and profitable; detailed current P&L not public | F7: High / Medium | G7: https://www.spectrumequity.com/insights/partners-in-conversation-powering-creators-building-for-the-long-game/
A8: Linktree 70M+ users; broader link-in-bio platform | B8: ~$55.5M revenue 2024 estimate | D8: No reliable standalone public cost P&L located | F8: Medium / Low | G8: https://sacra.com/c/linktree/
A9: Gumroad SEC-filed creator-commerce financials | B9: $17.8M revenue 2025 actual | D9: $6.1M COGS; $3.8M net income | F9: High | G9: https://www.sec.gov/Archives/edgar/data/1532978/0001532978-26-000003-index.htm
A10: Shopify $378.4B GMV; much broader commerce platform | B10: $11.6B revenue 2025 actual | D10: $6.0B COGS; $4.1B OpEx; $1.47B operating income | F10: High | G10: https://www.sec.gov/Archives/edgar/data/1594805/000159480526000007/shop-20251231.htm
A11: Flodesk 50 FTE and 80K paying customers at May-2024 interview | B11: >$36M ARR 2025 | D11: Profitable; paid ads were ~$700K/quarter in May-2024 founder interview | F11: High / Medium | G11: https://flodesk.com/blog/a-milestone-year-made-together/ https://getlatka.com/companies/flodesk/interviews/flodesk-rebecca-shostak-2024
A12: Bio.Site Squarespace product; no standalone P&L | B12: Not separately disclosed | D12: Not separately disclosed | F12: High | G12: https://www.squarespace.com/marketing/biosite
A13: Podia Creator-focused all-in-one commerce / content platform | B13: Not publicly disclosed | D13: Company states it is profitable and independent | F13: High | G13: https://www.podia.com/about
A14: Teachable Owned by Hotmart; 200K+ creators across Hotmart + Teachable (2024) | B14: Standalone revenue not disclosed $10B+ cumulative GMV across Hotmart + Teachable | D14: Standalone costs not disclosed | F14: High for GMV | G14: https://www.teachable.com/press/hotmart-company-announces-10-billion
A16: Benchmarking note: Gumroad and Shopify provide the strongest public cost data. Stan, Kajabi, Flodesk and Podia are useful operating-model references, while Beacons and Linktree revenue figures above are third-party estimates.

Sheet Seed Raise Plan
A2: Funding Assumptions
A3: Seed Raise Amount | B3: 5000000
A4: Funding Year | B4: 2026
A6: Funding %
A7: Software Tools | B7: 0.05 | C7: =B7*$B$3 -> 250000
A8: Hiring | B8: 0.8 | C8: =B8*$B$3 -> 4000000
A9: Marketing | B9: 0.15 | C9: =B9*$B$3 -> 750000
A10: Sum | B10: =SUM(B7:B9) -> 1 | C10: =B10*$B$3 -> 5000000
A12: Compensation Assumptions
A13: Role | B13: Average Salary | C13: Annual Raise
A14: CEO | B14: 60000 | C14: 0.25
A15: Product Manager | B15: 60000 | C15: 0.1
A16: Engineer | B16: 90000 | C16: 0.05
A17: Chief of Staff | B17: 90000 | C17: 0.1
A19: Hiring Priority Plan
A20: Priority | B20: Role | C20: # Hires | D20: Minimum Seed Raise | E20: Base Annual Salary | F20: Annual Raise | G20: Funded? | H20: Hire Year | I20: Sequence Check
A21: 1 | B21: CEO | C21: 1 | D21: 200000 | E21: =IFERROR(INDEX($B$14:$B$17,MATCH(B21,$A$14:$A$17,0)),"") -> 60000 | F21: =IFERROR(INDEX($C$14:$C$17,MATCH(B21,$A$14:$A$17,0)),"") -> 0.25 | G21: =IF($C$8>=D21,"Yes","No") -> Yes | H21: =IF(AND(G21="Yes",$B$4<>""),$B$4,"") -> 2026 | I21: OK
A22: 2 | B22: Engineer | C22: 1 | D22: 300000 | E22: =IFERROR(INDEX($B$14:$B$17,MATCH(B22,$A$14:$A$17,0)),"") -> 90000 | F22: =IFERROR(INDEX($C$14:$C$17,MATCH(B22,$A$14:$A$17,0)),"") -> 0.05 | G22: =IF(AND($C$8>=D22,G21="Yes"),"Yes","No") -> Yes | H22: =IF(AND(G22="Yes",$B$4<>""),$B$4,"") -> 2026 | I22: =IF(D22>D21,"OK","CHECK") -> OK
A23: 3 | B23: Chief of Staff | C23: 1 | D23: 600000 | E23: =IFERROR(INDEX($B$14:$B$17,MATCH(B23,$A$14:$A$17,0)),"") -> 90000 | F23: =IFERROR(INDEX($C$14:$C$17,MATCH(B23,$A$14:$A$17,0)),"") -> 0.1 | G23: =IF(AND($C$8>=D23,G22="Yes"),"Yes","No") -> Yes | H23: =IF(AND(G23="Yes",$B$4<>""),$B$4,"") -> 2026 | I23: =IF(D23>D22,"OK","CHECK") -> OK
A24: 4 | B24: Engineer | C24: 1 | D24: 900000 | E24: =IFERROR(INDEX($B$14:$B$17,MATCH(B24,$A$14:$A$17,0)),"") -> 90000 | F24: =IFERROR(INDEX($C$14:$C$17,MATCH(B24,$A$14:$A$17,0)),"") -> 0.05 | G24: =IF(AND($C$8>=D24,G23="Yes"),"Yes","No") -> Yes | H24: =IF(AND(G24="Yes",$B$4<>""),$B$4,"") -> 2026 | I24: =IF(D24>D23,"OK","CHECK") -> OK
A25: 5 | B25: Product Manager | C25: 1 | D25: 1200000 | E25: =IFERROR(INDEX($B$14:$B$17,MATCH(B25,$A$14:$A$17,0)),"") -> 60000 | F25: =IFERROR(INDEX($C$14:$C$17,MATCH(B25,$A$14:$A$17,0)),"") -> 0.1 | G25: =IF(AND($C$8>=D25,G24="Yes"),"Yes","No") -> Yes | H25: =IF(AND(G25="Yes",$B$4<>""),$B$4,"") -> 2026 | I25: =IF(D25>D24,"OK","CHECK") -> OK
A27: Hiring logic: Seed Raise Amount determines how far down the strict priority list the company can hire. All positions whose funding thresholds are met are hired in the Funding Year, with a full year of salary in that year. Annual raises apply beginning in the following year. No employee attrition is assumed in this schedule.
A30: Yearly Hiring & Compensation Plan
B31: 2026E | C31: 2027F | D31: 2028F | E31: 2029F | F31: 2030F | G31: 2031F
B32: 2026 | C32: 2027 | D32: 2028 | E32: 2029 | F32: 2030 | G32: 2031
A33: Headcount by Role
A34: CEO | B34: =IF(AND($G$21="Yes",$H$21<=B$32),$C$21,0) -> 1 | C34: =IF(AND($G$21="Yes",$H$21<=C$32),$C$21,0) -> 1 | D34: =IF(AND($G$21="Yes",$H$21<=D$32),$C$21,0) -> 1 | E34: =IF(AND($G$21="Yes",$H$21<=E$32),$C$21,0) -> 1 | F34: =IF(AND($G$21="Yes",$H$21<=F$32),$C$21,0) -> 1 | G34: =IF(AND($G$21="Yes",$H$21<=G$32),$C$21,0) -> 1
A35: Engineers | B35: =IF(AND($G$22="Yes",$H$22<=B$32),$C$22,0)+IF(AND($G$24="Yes",$H$24<=B$32),$C$24,0) -> 2 | C35: =IF(AND($G$22="Yes",$H$22<=C$32),$C$22,0)+IF(AND($G$24="Yes",$H$24<=C$32),$C$24,0) -> 2 | D35: =IF(AND($G$22="Yes",$H$22<=D$32),$C$22,0)+IF(AND($G$24="Yes",$H$24<=D$32),$C$24,0) -> 2 | E35: =IF(AND($G$22="Yes",$H$22<=E$32),$C$22,0)+IF(AND($G$24="Yes",$H$24<=E$32),$C$24,0) -> 2 | F35: =IF(AND($G$22="Yes",$H$22<=F$32),$C$22,0)+IF(AND($G$24="Yes",$H$24<=F$32),$C$24,0) -> 2 | G35: =IF(AND($G$22="Yes",$H$22<=G$32),$C$22,0)+IF(AND($G$24="Yes",$H$24<=G$32),$C$24,0) -> 2
A36: Chief of Staff | B36: =IF(AND($G$23="Yes",$H$23<=B$32),$C$23,0) -> 1 | C36: =IF(AND($G$23="Yes",$H$23<=C$32),$C$23,0) -> 1 | D36: =IF(AND($G$23="Yes",$H$23<=D$32),$C$23,0) -> 1 | E36: =IF(AND($G$23="Yes",$H$23<=E$32),$C$23,0) -> 1 | F36: =IF(AND($G$23="Yes",$H$23<=F$32),$C$23,0) -> 1 | G36: =IF(AND($G$23="Yes",$H$23<=G$32),$C$23,0) -> 1
A37: Product Manager | B37: =IF(AND($G$25="Yes",$H$25<=B$32),$C$25,0) -> 1 | C37: =IF(AND($G$25="Yes",$H$25<=C$32),$C$25,0) -> 1 | D37: =IF(AND($G$25="Yes",$H$25<=D$32),$C$25,0) -> 1 | E37: =IF(AND($G$25="Yes",$H$25<=E$32),$C$25,0) -> 1 | F37: =IF(AND($G$25="Yes",$H$25<=F$32),$C$25,0) -> 1 | G37: =IF(AND($G$25="Yes",$H$25<=G$32),$C$25,0) -> 1
A38: Total Headcount | B38: =SUM(B34:B37) -> 5 | C38: =SUM(C34:C37) -> 5 | D38: =SUM(D34:D37) -> 5 | E38: =SUM(E34:E37) -> 5 | F38: =SUM(F34:F37) -> 5 | G38: =SUM(G34:G37) -> 5
A40: Annual Cash Compensation
A41: CEO | B41: =IF(AND($G$21="Yes",$H$21<=B$32),$C$21*$E$21*(1+$F$21)^(B$32-$H$21),0) -> 60000 | C41: =IF(AND($G$21="Yes",$H$21<=C$32),$C$21*$E$21*(1+$F$21)^(C$32-$H$21),0) -> 75000 | D41: =IF(AND($G$21="Yes",$H$21<=D$32),$C$21*$E$21*(1+$F$21)^(D$32-$H$21),0) -> 93750 | E41: =IF(AND($G$21="Yes",$H$21<=E$32),$C$21*$E$21*(1+$F$21)^(E$32-$H$21),0) -> 117187.5 | F41: =IF(AND($G$21="Yes",$H$21<=F$32),$C$21*$E$21*(1+$F$21)^(F$32-$H$21),0) -> 146484.38 | G41: =IF(AND($G$21="Yes",$H$21<=G$32),$C$21*$E$21*(1+$F$21)^(G$32-$H$21),0) -> 183105.47
A42: Engineers | B42: =IF(AND($G$22="Yes",$H$22<=B$32),$C$22*$E$22*(1+$F$22)^(B$32-$H$22),0)+IF(AND($G$24="Yes",$H$24<=B$32),$C$24*$E$24*(1+$F$24)^(B$32-$H$24),0) -> 180000 | C42: =IF(AND($G$22="Yes",$H$22<=C$32),$C$22*$E$22*(1+$F$22)^(C$32-$H$22),0)+IF(AND($G$24="Yes",$H$24<=C$32),$C$24*$E$24*(1+$F$24)^(C$32-$H$24),0) -> 189000 | D42: =IF(AND($G$22="Yes",$H$22<=D$32),$C$22*$E$22*(1+$F$22)^(D$32-$H$22),0)+IF(AND($G$24="Yes",$H$24<=D$32),$C$24*$E$24*(1+$F$24)^(D$32-$H$24),0) -> 198450 | E42: =IF(AND($G$22="Yes",$H$22<=E$32),$C$22*$E$22*(1+$F$22)^(E$32-$H$22),0)+IF(AND($G$24="Yes",$H$24<=E$32),$C$24*$E$24*(1+$F$24)^(E$32-$H$24),0) -> 208372.5 | F42: =IF(AND($G$22="Yes",$H$22<=F$32),$C$22*$E$22*(1+$F$22)^(F$32-$H$22),0)+IF(AND($G$24="Yes",$H$24<=F$32),$C$24*$E$24*(1+$F$24)^(F$32-$H$24),0) -> 218791.12 | G42: =IF(AND($G$22="Yes",$H$22<=G$32),$C$22*$E$22*(1+$F$22)^(G$32-$H$22),0)+IF(AND($G$24="Yes",$H$24<=G$32),$C$24*$E$24*(1+$F$24)^(G$32-$H$24),0) -> 229730.68
A43: Chief of Staff | B43: =IF(AND($G$23="Yes",$H$23<=B$32),$C$23*$E$23*(1+$F$23)^(B$32-$H$23),0) -> 90000 | C43: =IF(AND($G$23="Yes",$H$23<=C$32),$C$23*$E$23*(1+$F$23)^(C$32-$H$23),0) -> 99000 | D43: =IF(AND($G$23="Yes",$H$23<=D$32),$C$23*$E$23*(1+$F$23)^(D$32-$H$23),0) -> 108900 | E43: =IF(AND($G$23="Yes",$H$23<=E$32),$C$23*$E$23*(1+$F$23)^(E$32-$H$23),0) -> 119790 | F43: =IF(AND($G$23="Yes",$H$23<=F$32),$C$23*$E$23*(1+$F$23)^(F$32-$H$23),0) -> 131769 | G43: =IF(AND($G$23="Yes",$H$23<=G$32),$C$23*$E$23*(1+$F$23)^(G$32-$H$23),0) -> 144945.9
A44: Product Manager | B44: =IF(AND($G$25="Yes",$H$25<=B$32),$C$25*$E$25*(1+$F$25)^(B$32-$H$25),0) -> 60000 | C44: =IF(AND($G$25="Yes",$H$25<=C$32),$C$25*$E$25*(1+$F$25)^(C$32-$H$25),0) -> 66000 | D44: =IF(AND($G$25="Yes",$H$25<=D$32),$C$25*$E$25*(1+$F$25)^(D$32-$H$25),0) -> 72600 | E44: =IF(AND($G$25="Yes",$H$25<=E$32),$C$25*$E$25*(1+$F$25)^(E$32-$H$25),0) -> 79860 | F44: =IF(AND($G$25="Yes",$H$25<=F$32),$C$25*$E$25*(1+$F$25)^(F$32-$H$25),0) -> 87846 | G44: =IF(AND($G$25="Yes",$H$25<=G$32),$C$25*$E$25*(1+$F$25)^(G$32-$H$25),0) -> 96630.6
A45: Total Cash Compensation | B45: =SUM(B41:B44) -> 390000 | C45: =SUM(C41:C44) -> 429000 | D45: =SUM(D41:D44) -> 473700 | E45: =SUM(E41:E44) -> 525210 | F45: =SUM(F41:F44) -> 584890.5 | G45: =SUM(G41:G44) -> 654412.65
A47: New Hires in Year
A48: Total New Hires | B48: =IF($H$21=B$32,$C$21,0)+IF($H$22=B$32,$C$22,0)+IF($H$23=B$32,$C$23,0)+IF($H$24=B$32,$C$24,0)+IF($H$25=B$32,$C$25,0) -> 5 | C48: =IF($H$21=C$32,$C$21,0)+IF($H$22=C$32,$C$22,0)+IF($H$23=C$32,$C$23,0)+IF($H$24=C$32,$C$24,0)+IF($H$25=C$32,$C$25,0) -> 0 | D48: =IF($H$21=D$32,$C$21,0)+IF($H$22=D$32,$C$22,0)+IF($H$23=D$32,$C$23,0)+IF($H$24=D$32,$C$24,0)+IF($H$25=D$32,$C$25,0) -> 0 | E48: =IF($H$21=E$32,$C$21,0)+IF($H$22=E$32,$C$22,0)+IF($H$23=E$32,$C$23,0)+IF($H$24=E$32,$C$24,0)+IF($H$25=E$32,$C$25,0) -> 0 | F48: =IF($H$21=F$32,$C$21,0)+IF($H$22=F$32,$C$22,0)+IF($H$23=F$32,$C$23,0)+IF($H$24=F$32,$C$24,0)+IF($H$25=F$32,$C$25,0) -> 0 | G48: =IF($H$21=G$32,$C$21,0)+IF($H$22=G$32,$C$22,0)+IF($H$23=G$32,$C$23,0)+IF($H$24=G$32,$C$24,0)+IF($H$25=G$32,$C$25,0) -> 0
